Workbook

Sheet Setup
A1: SOLID GROUND - Business Setup
A3: Fill in this sheet first. Your details flow through to all other sheets.
A5: Business name | C5: Your trading name
A6: Owner name | C6: Your full name
A7: Business start date | C7: When you started or plan to start
A8: Business structure | B8: Sole Trader | C8: Sole Trader / Partnership / Company
A9: ABN | C9: 11 digits - e.g. 12 345 678 901
A10: GST registered? | B10: No | C10: Yes or No
A11: GST rate | B11: 0.1 | C11: Default 10% - only applies if GST registered
A12: Tax-free threshold | B12: 18200 | C12: 2024-25: $18,200 - income below this is tax-free

Sheet Household Budget
A1: HOUSEHOLD BUDGET
A2: This sheet is about YOUR home finances, not the business. Understanding what you need personally each month helps you know what the business needs to bring in.
A4: Category | B4: Jan | C4: Feb | D4: Mar | E4: Apr | F4: May | G4: Jun | H4: Jul | I4: Aug | J4: Sep | K4: Oct | L4: Nov | M4: Dec | N4: Annual Total
A5: INCOME
A6: Casual/Part-time wages | N6: =SUM(B6:M6) -> 0
A7: Government payments (FTB, Carers, other) | N7: =SUM(B7:M7) -> 0
A8: Business drawings (from this business) | N8: =SUM(B8:M8) -> 0
A9: Other income | N9: =SUM(B9:M9) -> 0
A10: Child support / maintenance | N10: =SUM(B10:M10) -> 0
A11: TOTAL INCOME | B11: =SUM(B6:B10) -> 0 | C11: =SUM(C6:C10) -> 0 | D11: =SUM(D6:D10) -> 0 | E11: =SUM(E6:E10) -> 0 | F11: =SUM(F6:F10) -> 0 | G11: =SUM(G6:G10) -> 0 | H11: =SUM(H6:H10) -> 0 | I11: =SUM(I6:I10) -> 0 | ... N11: =SUM(N6:N10) -> 0
A13: EXPENSES
A14: HOME
A15: Rent or mortgage | N15: =SUM(B15:M15) -> 0
A16: Groceries | N16: =SUM(B16:M16) -> 0
A17: Gas & electricity | N17: =SUM(B17:M17) -> 0
A18: Water | N18: =SUM(B18:M18) -> 0
A19: Home insurance | N19: =SUM(B19:M19) -> 0
A20: School fees / childcare | N20: =SUM(B20:M20) -> 0
A21: PERSONAL
A22: Clothing | N22: =SUM(B22:M22) -> 0
A23: Medical / health insurance | N23: =SUM(B23:M23) -> 0
A24: Entertainment | N24: =SUM(B24:M24) -> 0
A25: Pets | N25: =SUM(B25:M25) -> 0
A26: Personal care | N26: =SUM(B26:M26) -> 0
A27: Professional development / courses
A28: TRANSPORT
A29: Fuel | N29: =SUM(B28:M28) -> 0
A30: Vehicle insurance & registration | N30: =SUM(B29:M29) -> 0
A31: Vehicle maintenance | N31: =SUM(B30:M30) -> 0
A32: COMMUNICATION
A33: Phone (home/mobile) | N33: =SUM(B32:M32) -> 0
A34: Internet | N34: =SUM(B33:M33) -> 0
A35: DEBT PAYMENTS
A36: Credit card minimum payments | N36: =SUM(B35:M35) -> 0
A37: Personal loan repayments | N37: =SUM(B36:M36) -> 0
A38: Other debt | N38: =SUM(B37:M37) -> 0
A39: (spare - add your own) | N39: =SUM(B38:M38) -> 0
A40: (spare - add your own) | N40: =SUM(B39:M39) -> 0
A41: TOTAL EXPENSES | B41: =SUM(B14:B39) -> 0 | C41: =SUM(C14:C39) -> 0 | D41: =SUM(D14:D39) -> 0 | E41: =SUM(E14:E39) -> 0 | F41: =SUM(F14:F39) -> 0 | G41: =SUM(G14:G39) -> 0 | H41: =SUM(H14:H39) -> 0 | I41: =SUM(I14:I39) -> 0 | ... N41: =SUM(N14:N39) -> 0
A42: SURPLUS / DEFICIT | B42: =B11-B40 -> 0 | C42: =C11-C40 -> 0 | D42: =D11-D40 -> 0 | E42: =E11-E40 -> 0 | F42: =F11-F40 -> 0 | G42: =G11-G40 -> 0 | H42: =H11-H40 -> 0 | I42: =I11-I40 -> 0 | ... N42: =N11-N40 -> 0
...

Sheet Shared Expenses
A1: SHARED EXPENSES - Personal vs Business Split
A2: If you use something for both personal and business purposes, split it here. Only the business % is tax-deductible.
A4: ONGOING SHARED EXPENSES
A5: Item | B5: Monthly Cost | C5: % Personal | D5: % Business | E5: $ Personal/month | F5: $ Business/month
A6: Home phone | B6: 0 | C6: 0.5 | D6: =1-C6 -> 0.5 | E6: =B6*C6 -> 0 | F6: =B6*D6 -> 0
A7: Internet | B7: 0 | C7: 0.5 | D7: =1-C7 -> 0.5 | E7: =B7*C7 -> 0 | F7: =B7*D7 -> 0
A8: Mobile phone | B8: 0 | C8: 0.5 | D8: =1-C8 -> 0.5 | E8: =B8*C8 -> 0 | F8: =B8*D8 -> 0
A9: Motor vehicle - insurance | B9: 0 | C9: 0.5 | D9: =1-C9 -> 0.5 | E9: =B9*C9 -> 0 | F9: =B9*D9 -> 0
A10: Motor vehicle - registration | B10: 0 | C10: 0.5 | D10: =1-C10 -> 0.5 | E10: =B10*C10 -> 0 | F10: =B10*D10 -> 0
A11: Motor vehicle - maintenance/fuel | B11: 0 | C11: 0.5 | D11: =1-C11 -> 0.5 | E11: =B11*C11 -> 0 | F11: =B11*D11 -> 0
A12: Home office (utilities portion) | B12: 0 | C12: 0.5 | D12: =1-C12 -> 0.5 | E12: =B12*C12 -> 0 | F12: =B12*D12 -> 0
A13: Spare 1 | B13: 0 | C13: 0.5 | D13: =1-C13 -> 0.5 | E13: =B13*C13 -> 0 | F13: =B13*D13 -> 0
A14: Spare 2 | B14: 0 | C14: 0.5 | D14: =1-C14 -> 0.5 | E14: =B14*C14 -> 0 | F14: =B14*D14 -> 0
A15: TOTAL | B15: =SUM(B6:B14) -> 0 | E15: =SUM(E6:E14) -> 0 | F15: =SUM(F6:F14) -> 0
A17: SHARED ASSETS (brought into / used in business)
A18: Item | B18: Value | C18: % Personal | D18: % Business | E18: $ Personal | F18: $ Business
A19: Furniture & equipment | B19: 0 | C19: 0.5 | D19: =1-C19 -> 0.5 | E19: =B19*C19 -> 0 | F19: =B19*D19 -> 0
A20: Computer / laptop | B20: 0 | C20: 0.5 | D20: =1-C20 -> 0.5 | E20: =B20*C20 -> 0 | F20: =B20*D20 -> 0
A21: Motor vehicle | B21: 0 | C21: 0.5 | D21: =1-C21 -> 0.5 | E21: =B21*C21 -> 0 | F21: =B21*D21 -> 0
A22: Mobile phone | B22: 0 | C22: 0.5 | D22: =1-C22 -> 0.5 | E22: =B22*C22 -> 0 | F22: =B22*D22 -> 0
A23: Tools / equipment | B23: 0 | C23: 0.5 | D23: =1-C23 -> 0.5 | E23: =B23*C23 -> 0 | F23: =B23*D23 -> 0
A24: Spare | B24: 0 | C24: 0.5 | D24: =1-C24 -> 0.5 | E24: =B24*C24 -> 0 | F24: =B24*D24 -> 0
A25: TOTAL | B25: =SUM(B19:B24) -> 0 | E25: =SUM(E19:E24) -> 0 | F25: =SUM(F19:F24) -> 0

Sheet Service Pricing
A1: Service Pricing Calculator
A2: Module 6 - Solid Ground | Fill in the yellow cells
A4: STEP 1 — Your weekly expenses
A5: Weekly business expenses | C5: Rent, insurance, software, subscriptions, supplies
A6: Weekly personal expenses | C6: Rent/mortgage, groceries, bills - what you need to live on
A7: Business expenses target (first goal) | B7: =IF(B5>0,B5,"")
A8: Full income target (business + personal) | B8: =IF((B5+B6)>0,B5+B6,"")
A10: STEP 2 — Your hourly rate
A11: My hourly rate (current or considering) | C11: What you charge per hour or per session
A13: STEP 3 — Realistic client hours per week
A14: Hours I CAN see clients | C14: Max available hours
A15: Hours I WANT to see clients | C15: What feels right and sustainable
A17: STEP 4 — What your rate earns you
A18: Income at your rate x hours you CAN work | B18: =IFERROR(B11*B14,"") -> 0
A19: Income at your rate x hours you WANT to work | B19: =IFERROR(B11*B15,"") -> 0
A21: Hours needed to cover business expenses (at your rate) | B21: =IFERROR(IF(B11>0,B5/B11,""),"")
A22: Hours needed to cover full expenses (at your rate) | B22: =IFERROR(IF(B11>0,(B5+B6)/B11,""),"")
A24: STEP 5 — Gap check
A25: Does your rate cover business expenses at WANT hours? | B25: =IFERROR(IF(B15*B11>=B5,"Yes - covered","Gap - see below"),"") -> Yes - covered
A26: Rate needed to cover business expenses at WANT hours | B26: =IFERROR(IF(B15>0,B5/B15,""),"")
A27: Rate needed to cover FULL expenses at WANT hours | B27: =IFERROR(IF(B15>0,(B5+B6)/B15,""),"")
A29: Your starting price is not your forever price. Begin with a number you can say without flinching. Revisit after 6-12 months.

Sheet Sales Forecast
A1: SALES FORECAST
A2: List every service or product you plan to sell. Be realistic - start with conservative estimates.
A4: SALES - Monthly Units Sold
A5: Service / Product | B5: Price per unit | C5: Jan | D5: Feb | E5: Mar | F5: Apr | G5: May | H5: Jun | I5: Jul | J5: Aug | K5: Sep | L5: Oct | M5: Nov | N5: Dec | O5: Annual Total | P5: % of Sales
A6: Service/Product 1 | B6: 0 | C6: 0 | D6: 0 | E6: 0 | F6: 0 | G6: 0 | H6: 0 | I6: 0 | J6: 0 | K6: 0 | L6: 0 | M6: 0 | N6: 0 | O6: =B6*SUM(C6:N6) -> 0 | P6: =IFERROR(P6/P$16,0)
A7: Service/Product 2 | B7: 0 | C7: 0 | D7: 0 | E7: 0 | F7: 0 | G7: 0 | H7: 0 | I7: 0 | J7: 0 | K7: 0 | L7: 0 | M7: 0 | N7: 0 | O7: =B7*SUM(C7:N7) -> 0 | P7: =IFERROR(P7/P$16,0)
A8: Service/Product 3 | B8: 0 | C8: 0 | D8: 0 | E8: 0 | F8: 0 | G8: 0 | H8: 0 | I8: 0 | J8: 0 | K8: 0 | L8: 0 | M8: 0 | N8: 0 | O8: =B8*SUM(C8:N8) -> 0 | P8: =IFERROR(P8/P$16,0)
A9: Service/Product 4 | B9: 0 | C9: 0 | D9: 0 | E9: 0 | F9: 0 | G9: 0 | H9: 0 | I9: 0 | J9: 0 | K9: 0 | L9: 0 | M9: 0 | N9: 0 | O9: =B9*SUM(C9:N9) -> 0 | P9: =IFERROR(P9/P$16,0)
A10: Service/Product 5 | B10: 0 | C10: 0 | D10: 0 | E10: 0 | F10: 0 | G10: 0 | H10: 0 | I10: 0 | J10: 0 | K10: 0 | L10: 0 | M10: 0 | N10: 0 | O10: =B10*SUM(C10:N10) -> 0 | P10: =IFERROR(P10/P$16,0)
A11: Service/Product 6 | B11: 0 | C11: 0 | D11: 0 | E11: 0 | F11: 0 | G11: 0 | H11: 0 | I11: 0 | J11: 0 | K11: 0 | L11: 0 | M11: 0 | N11: 0 | O11: =B11*SUM(C11:N11) -> 0 | P11: =IFERROR(P11/P$16,0)
A12: Service/Product 7 | B12: 0 | C12: 0 | D12: 0 | E12: 0 | F12: 0 | G12: 0 | H12: 0 | I12: 0 | J12: 0 | K12: 0 | L12: 0 | M12: 0 | N12: 0 | O12: =B12*SUM(C12:N12) -> 0 | P12: =IFERROR(P12/P$16,0)
A13: Service/Product 8 | B13: 0 | C13: 0 | D13: 0 | E13: 0 | F13: 0 | G13: 0 | H13: 0 | I13: 0 | J13: 0 | K13: 0 | L13: 0 | M13: 0 | N13: 0 | O13: =B13*SUM(C13:N13) -> 0 | P13: =IFERROR(P13/P$16,0)
A14: Service/Product 9 | B14: 0 | C14: 0 | D14: 0 | E14: 0 | F14: 0 | G14: 0 | H14: 0 | I14: 0 | J14: 0 | K14: 0 | L14: 0 | M14: 0 | N14: 0 | O14: =B14*SUM(C14:N14) -> 0 | P14: =IFERROR(P14/P$16,0)
A15: Service/Product 10 | B15: 0 | C15: 0 | D15: 0 | E15: 0 | F15: 0 | G15: 0 | H15: 0 | I15: 0 | J15: 0 | K15: 0 | L15: 0 | M15: 0 | N15: 0 | O15: =B15*SUM(C15:N15) -> 0 | P15: =IFERROR(P15/P$16,0)
A16: TOTAL SALES | C16: =SUM(C6:C15) -> 0 | D16: =SUM(D6:D15) -> 0 | E16: =SUM(E6:E15) -> 0 | F16: =SUM(F6:F15) -> 0 | G16: =SUM(G6:G15) -> 0 | H16: =SUM(H6:H15) -> 0 | I16: =SUM(I6:I15) -> 0 | J16: =SUM(J6:J15) -> 0 | ... N16: =SUM(N6:N15) -> 0 | O16: =SUM(P6:P15) | P16: =IFERROR(1,0) -> 1
A18: PAYMENT TIMING
A19: When do customers actually pay you? For most service businesses, leave at 100% same month.
A20: % collected same month | B20: 1
A21: % collected 1 month later | B21: 0
A22: % collected 2+ months later | B22: 0
A23: Total (must = 100%) | B23: =B20+B21+B22 -> 1
A24: Total banked per month | C24: =C16*$B$20 -> 0 | D24: =D16*$B$20+C16*$B$21 -> 0 | E24: =E16*$B$20+D16*$B$21+C16*$B$22 -> 0 | F24: =F16*$B$20+E16*$B$21+D16*$B$22 -> 0 | G24: =G16*$B$20+F16*$B$21+E16*$B$22 -> 0 | H24: =H16*$B$20+G16*$B$21+F16*$B$22 -> 0 | I24: =I16*$B$20+H16*$B$21+G16*$B$22 -> 0 | J24: =J16*$B$20+I16*$B$21+H16*$B$22 -> 0 | K24: =K16*$B$20+J16*$B$21+I16*$B$22 -> 0 | L24: =L16*$B$20+K16*$B$21+J16*$B$22 -> 0 | ... N24: =N16*$B$20+M16*$B$21+L16*$B$22 -> 0 | O24: =SUM(C24:N24) -> 0
A26: VARIABLE COSTS
A27: Variable costs are costs that change directly with your sales - materials, supplies, direct costs per job. If you are a pure service business, these may be zero.
A28: Service / Product | B28: Cost per unit | C28: Jan | D28: Feb | E28: Mar | F28: Apr | G28: May | H28: Jun | I28: Jul | J28: Aug | K28: Sep | L28: Oct | M28: Nov | N28: Dec | O28: Annual Total
A29: ='Sales Forecast'!A6 -> Service/Product 1 | B29: 0 | C29: =C6*B29 -> 0 | D29: =D6*B29 -> 0 | E29: =E6*B29 -> 0 | F29: =F6*B29 -> 0 | G29: =G6*B29 -> 0 | H29: =H6*B29 -> 0 | I29: =I6*B29 -> 0 | J29: =J6*B29 -> 0 | K29: =K6*B29 -> 0 | L29: =L6*B29 -> 0 | M29: =M6*B29 -> 0 | N29: =N6*B29 -> 0 | O29: =SUM(C29:N29) -> 0
A30: ='Sales Forecast'!A7 -> Service/Product 2 | B30: 0 | C30: =C7*B30 -> 0 | D30: =D7*B30 -> 0 | E30: =E7*B30 -> 0 | F30: =F7*B30 -> 0 | G30: =G7*B30 -> 0 | H30: =H7*B30 -> 0 | I30: =I7*B30 -> 0 | J30: =J7*B30 -> 0 | K30: =K7*B30 -> 0 | L30: =L7*B30 -> 0 | M30: =M7*B30 -> 0 | N30: =N7*B30 -> 0 | O30: =SUM(C30:N30) -> 0
A31: ='Sales Forecast'!A8 -> Service/Product 3 | B31: 0 | C31: =C8*B31 -> 0 | D31: =D8*B31 -> 0 | E31: =E8*B31 -> 0 | F31: =F8*B31 -> 0 | G31: =G8*B31 -> 0 | H31: =H8*B31 -> 0 | I31: =I8*B31 -> 0 | J31: =J8*B31 -> 0 | K31: =K8*B31 -> 0 | L31: =L8*B31 -> 0 | M31: =M8*B31 -> 0 | N31: =N8*B31 -> 0 | O31: =SUM(C31:N31) -> 0
A32: ='Sales Forecast'!A9 -> Service/Product 4 | B32: 0 | C32: =C9*B32 -> 0 | D32: =D9*B32 -> 0 | E32: =E9*B32 -> 0 | F32: =F9*B32 -> 0 | G32: =G9*B32 -> 0 | H32: =H9*B32 -> 0 | I32: =I9*B32 -> 0 | J32: =J9*B32 -> 0 | K32: =K9*B32 -> 0 | L32: =L9*B32 -> 0 | M32: =M9*B32 -> 0 | N32: =N9*B32 -> 0 | O32: =SUM(C32:N32) -> 0
A33: ='Sales Forecast'!A10 -> Service/Product 5 | B33: 0 | C33: =C10*B33 -> 0 | D33: =D10*B33 -> 0 | E33: =E10*B33 -> 0 | F33: =F10*B33 -> 0 | G33: =G10*B33 -> 0 | H33: =H10*B33 -> 0 | I33: =I10*B33 -> 0 | J33: =J10*B33 -> 0 | K33: =K10*B33 -> 0 | L33: =L10*B33 -> 0 | M33: =M10*B33 -> 0 | N33: =N10*B33 -> 0 | O33: =SUM(C33:N33) -> 0
A34: ='Sales Forecast'!A11 -> Service/Product 6 | B34: 0 | C34: =C11*B34 -> 0 | D34: =D11*B34 -> 0 | E34: =E11*B34 -> 0 | F34: =F11*B34 -> 0 | G34: =G11*B34 -> 0 | H34: =H11*B34 -> 0 | I34: =I11*B34 -> 0 | J34: =J11*B34 -> 0 | K34: =K11*B34 -> 0 | L34: =L11*B34 -> 0 | M34: =M11*B34 -> 0 | N34: =N11*B34 -> 0 | O34: =SUM(C34:N34) -> 0
A35: ='Sales Forecast'!A12 -> Service/Product 7 | B35: 0 | C35: =C12*B35 -> 0 | D35: =D12*B35 -> 0 | E35: =E12*B35 -> 0 | F35: =F12*B35 -> 0 | G35: =G12*B35 -> 0 | H35: =H12*B35 -> 0 | I35: =I12*B35 -> 0 | J35: =J12*B35 -> 0 | K35: =K12*B35 -> 0 | L35: =L12*B35 -> 0 | M35: =M12*B35 -> 0 | N35: =N12*B35 -> 0 | O35: =SUM(C35:N35) -> 0
A36: ='Sales Forecast'!A13 -> Service/Product 8 | B36: 0 | C36: =C13*B36 -> 0 | D36: =D13*B36 -> 0 | E36: =E13*B36 -> 0 | F36: =F13*B36 -> 0 | G36: =G13*B36 -> 0 | H36: =H13*B36 -> 0 | I36: =I13*B36 -> 0 | J36: =J13*B36 -> 0 | K36: =K13*B36 -> 0 | L36: =L13*B36 -> 0 | M36: =M13*B36 -> 0 | N36: =N13*B36 -> 0 | O36: =SUM(C36:N36) -> 0
A37: ='Sales Forecast'!A14 -> Service/Product 9 | B37: 0 | C37: =C14*B37 -> 0 | D37: =D14*B37 -> 0 | E37: =E14*B37 -> 0 | F37: =F14*B37 -> 0 | G37: =G14*B37 -> 0 | H37: =H14*B37 -> 0 | I37: =I14*B37 -> 0 | J37: =J14*B37 -> 0 | K37: =K14*B37 -> 0 | L37: =L14*B37 -> 0 | M37: =M14*B37 -> 0 | N37: =N14*B37 -> 0 | O37: =SUM(C37:N37) -> 0
A38: ='Sales Forecast'!A15 -> Service/Product 10 | B38: 0 | C38: =C15*B38 -> 0 | D38: =D15*B38 -> 0 | E38: =E15*B38 -> 0 | F38: =F15*B38 -> 0 | G38: =G15*B38 -> 0 | H38: =H15*B38 -> 0 | I38: =I15*B38 -> 0 | J38: =J15*B38 -> 0 | K38: =K15*B38 -> 0 | L38: =L15*B38 -> 0 | M38: =M15*B38 -> 0 | N38: =N15*B38 -> 0 | O38: =SUM(C38:N38) -> 0
A39: TOTAL VARIABLE COSTS | C39: =SUM(C29:C38) -> 0 | D39: =SUM(D29:D38) -> 0 | E39: =SUM(E29:E38) -> 0 | F39: =SUM(F29:F38) -> 0 | G39: =SUM(G29:G38) -> 0 | H39: =SUM(H29:H38) -> 0 | I39: =SUM(I29:I38) -> 0 | J39: =SUM(J29:J38) -> 0 | ... N39: =SUM(N29:N38) -> 0 | O39: =SUM(P29:P38) -> 0

Sheet Marketing Plan
A1: MARKETING PLAN
A2: You don't need to spend on all of these. Mark only what you're planning to do. Leave everything else at zero.
A4: Item | B4: Monthly Cost | C4: Jan | D4: Feb | E4: Mar | F4: Apr | G4: May | H4: Jun | I4: Jul | J4: Aug | K4: Sep | L4: Oct | M4: Nov | N4: Dec | O4: Annual Total
A5: ONLINE PRESENCE
A6: Website (domain, hosting, design) | B6: 0 | C6: 0 | D6: 0 | E6: 0 | F6: 0 | G6: 0 | H6: 0 | I6: 0 | J6: 0 | K6: 0 | L6: 0 | M6: 0 | N6: 0 | O6: =SUM(C6:N6) -> 0
A7: Social media (content creation, tools) | B7: 0 | C7: 0 | D7: 0 | E7: 0 | F7: 0 | G7: 0 | H7: 0 | I7: 0 | J7: 0 | K7: 0 | L7: 0 | M7: 0 | N7: 0 | O7: =SUM(C7:N7) -> 0
A8: Google My Business setup | B8: 0 | C8: 0 | D8: 0 | E8: 0 | F8: 0 | G8: 0 | H8: 0 | I8: 0 | J8: 0 | K8: 0 | L8: 0 | M8: 0 | N8: 0 | O8: =SUM(C8:N8) -> 0
A9: Photography / brand assets | B9: 0 | C9: 0 | D9: 0 | E9: 0 | F9: 0 | G9: 0 | H9: 0 | I9: 0 | J9: 0 | K9: 0 | L9: 0 | M9: 0 | N9: 0 | O9: =SUM(C9:N9) -> 0
A10: CONTENT & ADVERTISING
A11: Paid social media advertising | B11: 0 | C11: 0 | D11: 0 | E11: 0 | F11: 0 | G11: 0 | H11: 0 | I11: 0 | J11: 0 | K11: 0 | L11: 0 | M11: 0 | N11: 0 | O11: =SUM(C11:N11) -> 0
A12: Google Ads | B12: 0 | C12: 0 | D12: 0 | E12: 0 | F12: 0 | G12: 0 | H12: 0 | I12: 0 | J12: 0 | K12: 0 | L12: 0 | M12: 0 | N12: 0 | O12: =SUM(C12:N12) -> 0
A13: Email marketing platform | B13: 0 | C13: 0 | D13: 0 | E13: 0 | F13: 0 | G13: 0 | H13: 0 | I13: 0 | J13: 0 | K13: 0 | L13: 0 | M13: 0 | N13: 0 | O13: =SUM(C13:N13) -> 0
A14: SEO / directory listings | B14: 0 | C14: 0 | D14: 0 | E14: 0 | F14: 0 | G14: 0 | H14: 0 | I14: 0 | J14: 0 | K14: 0 | L14: 0 | M14: 0 | N14: 0 | O14: =SUM(C14:N14) -> 0
A15: PRINTED MATERIALS
A16: Business cards | B16: 0 | C16: 0 | D16: 0 | E16: 0 | F16: 0 | G16: 0 | H16: 0 | I16: 0 | J16: 0 | K16: 0 | L16: 0 | M16: 0 | N16: 0 | O16: =SUM(C16:N16) -> 0
A17: Flyers / brochures | B17: 0 | C17: 0 | D17: 0 | E17: 0 | F17: 0 | G17: 0 | H17: 0 | I17: 0 | J17: 0 | K17: 0 | L17: 0 | M17: 0 | N17: 0 | O17: =SUM(C17:N17) -> 0
A18: Other printed materials | B18: 0 | C18: 0 | D18: 0 | E18: 0 | F18: 0 | G18: 0 | H18: 0 | I18: 0 | J18: 0 | K18: 0 | L18: 0 | M18: 0 | N18: 0 | O18: =SUM(C18:N18) -> 0
A19: NETWORKING & EVENTS
A20: Networking group memberships | B20: 0 | C20: 0 | D20: 0 | E20: 0 | F20: 0 | G20: 0 | H20: 0 | I20: 0 | J20: 0 | K20: 0 | L20: 0 | M20: 0 | N20: 0 | O20: =SUM(C20:N20) -> 0
A21: Events / markets / expos | B21: 0 | C21: 0 | D21: 0 | E21: 0 | F21: 0 | G21: 0 | H21: 0 | I21: 0 | J21: 0 | K21: 0 | L21: 0 | M21: 0 | N21: 0 | O21: =SUM(C21:N21) -> 0
A22: Sponsorships | B22: 0 | C22: 0 | D22: 0 | E22: 0 | F22: 0 | G22: 0 | H22: 0 | I22: 0 | J22: 0 | K22: 0 | L22: 0 | M22: 0 | N22: 0 | O22: =SUM(C22:N22) -> 0
A23: (spare) | B23: 0 | C23: 0 | D23: 0 | E23: 0 | F23: 0 | G23: 0 | H23: 0 | I23: 0 | J23: 0 | K23: 0 | L23: 0 | M23: 0 | N23: 0 | O23: =SUM(C23:N23) -> 0
A24: (spare) | B24: 0 | C24: 0 | D24: 0 | E24: 0 | F24: 0 | G24: 0 | H24: 0 | I24: 0 | J24: 0 | K24: 0 | L24: 0 | M24: 0 | N24: 0 | O24: =SUM(C24:N24) -> 0
A25: (spare) | B25: 0 | C25: 0 | D25: 0 | E25: 0 | F25: 0 | G25: 0 | H25: 0 | I25: 0 | J25: 0 | K25: 0 | L25: 0 | M25: 0 | N25: 0 | O25: =SUM(C25:N25) -> 0
A26: TOTAL MARKETING SPEND | C26: =SUM(C6:C25) -> 0 | D26: =SUM(D6:D25) -> 0 | E26: =SUM(E6:E25) -> 0 | F26: =SUM(F6:F25) -> 0 | G26: =SUM(G6:G25) -> 0 | H26: =SUM(H6:H25) -> 0 | I26: =SUM(I6:I25) -> 0 | J26: =SUM(J6:J25) -> 0 | ... O26: =SUM(O6:O25) -> 0

Sheet Cash Flow Budget
A1: CASH FLOW BUDGET
A3: Category | B3: Jan | C3: Feb | D3: Mar | E3: Apr | F3: May | G3: Jun | H3: Jul | I3: Aug | J3: Sep | K3: Oct | L3: Nov | M3: Dec | N3: Annual Total
A4: RECEIPTS
A5: Total sales banked (payment timing adjusted) | B5: ='Sales Forecast'!B24 -> 0 | C5: ='Sales Forecast'!C24 -> 0 | D5: ='Sales Forecast'!D24 -> 0 | E5: ='Sales Forecast'!E24 -> 0 | F5: ='Sales Forecast'!F24 -> 0 | G5: ='Sales Forecast'!G24 -> 0 | H5: ='Sales Forecast'!H24 -> 0 | I5: ='Sales Forecast'!I24 -> 0 | ... M5: ='Sales Forecast'!M24 -> 0 | N5: =SUM(B5:M5) -> 0
A6: Capital input (owner's own money put in) | B6: 0 | C6: 0 | D6: 0 | E6: 0 | F6: 0 | G6: 0 | H6: 0 | I6: 0 | J6: 0 | K6: 0 | L6: 0 | M6: 0 | N6: =SUM(B6:M6) -> 0
A7: Other receipts | B7: 0 | C7: 0 | D7: 0 | E7: 0 | F7: 0 | G7: 0 | H7: 0 | I7: 0 | J7: 0 | K7: 0 | L7: 0 | M7: 0 | N7: =SUM(B7:M7) -> 0
A8: GST collected (only if GST registered) | B8: =IF(Setup!$B$9="Yes",B5/11,0) -> 0 | C8: =IF(Setup!$B$9="Yes",C5/11,0) -> 0 | D8: =IF(Setup!$B$9="Yes",D5/11,0) -> 0 | E8: =IF(Setup!$B$9="Yes",E5/11,0) -> 0 | F8: =IF(Setup!$B$9="Yes",F5/11,0) -> 0 | G8: =IF(Setup!$B$9="Yes",G5/11,0) -> 0 | H8: =IF(Setup!$B$9="Yes",H5/11,0) -> 0 | I8: =IF(Setup!$B$9="Yes",I5/11,0) -> 0 | ... M8: =IF(Setup!$B$9="Yes",M5/11,0) -> 0 | N8: =SUM(B8:M8) -> 0
A9: TOTAL RECEIPTS | B9: =B5+B6+B7 -> 0 | C9: =C5+C6+C7 -> 0 | D9: =D5+D6+D7 -> 0 | E9: =E5+E6+E7 -> 0 | F9: =F5+F6+F7 -> 0 | G9: =G5+G6+G7 -> 0 | H9: =H5+H6+H7 -> 0 | I9: =I5+I6+I7 -> 0 | ... M9: =M5+M6+M7 -> 0 | N9: =SUM(B9:M9) -> 0
A11: VARIABLE COSTS OUT
A12: Total variable costs | B12: ='Sales Forecast'!B39 -> 0 | C12: ='Sales Forecast'!C39 -> 0 | D12: ='Sales Forecast'!D39 -> 0 | E12: ='Sales Forecast'!E39 -> 0 | F12: ='Sales Forecast'!F39 -> 0 | G12: ='Sales Forecast'!G39 -> 0 | H12: ='Sales Forecast'!H39 -> 0 | I12: ='Sales Forecast'!I39 -> 0 | ... M12: ='Sales Forecast'!M39 -> 0 | N12: =SUM(B12:M12) -> 0
A13: GST on variable costs (only if GST registered) | B13: =IF(Setup!$B$9="Yes",B12/11,0) -> 0 | C13: =IF(Setup!$B$9="Yes",C12/11,0) -> 0 | D13: =IF(Setup!$B$9="Yes",D12/11,0) -> 0 | E13: =IF(Setup!$B$9="Yes",E12/11,0) -> 0 | F13: =IF(Setup!$B$9="Yes",F12/11,0) -> 0 | G13: =IF(Setup!$B$9="Yes",G12/11,0) -> 0 | H13: =IF(Setup!$B$9="Yes",H12/11,0) -> 0 | I13: =IF(Setup!$B$9="Yes",I12/11,0) -> 0 | ... M13: =IF(Setup!$B$9="Yes",M12/11,0) -> 0 | N13: =SUM(B13:M13) -> 0
A14: CONTRIBUTION MARGIN | B14: =B5-B12 -> 0 | C14: =C5-C12 -> 0 | D14: =D5-D12 -> 0 | E14: =E5-E12 -> 0 | F14: =F5-F12 -> 0 | G14: =G5-G12 -> 0 | H14: =H5-H12 -> 0 | I14: =I5-I12 -> 0 | ... N14: =N5-N12 -> 0
A15: What is a contribution margin? Sales minus the direct costs of making those sales.
A17: OVERHEAD EXPENSES OUT
A18: Accountant / bookkeeper | B18: 0 | C18: 0 | D18: 0 | E18: 0 | F18: 0 | G18: 0 | H18: 0 | I18: 0 | J18: 0 | K18: 0 | L18: 0 | M18: 0 | N18: =SUM(B18:M18) -> 0
A19: Marketing | B19: ='Marketing Plan'!B26 -> 0 | C19: ='Marketing Plan'!C26 -> 0 | D19: ='Marketing Plan'!D26 -> 0 | E19: ='Marketing Plan'!E26 -> 0 | F19: ='Marketing Plan'!F26 -> 0 | G19: ='Marketing Plan'!G26 -> 0 | H19: ='Marketing Plan'!H26 -> 0 | I19: ='Marketing Plan'!I26 -> 0 | ... M19: ='Marketing Plan'!M26 -> 0 | N19: ='Marketing Plan'!O26 -> 0
A20: Electricity / gas | B20: 0 | C20: 0 | D20: 0 | E20: 0 | F20: 0 | G20: 0 | H20: 0 | I20: 0 | J20: 0 | K20: 0 | L20: 0 | M20: 0 | N20: =SUM(B20:M20) -> 0
A21: Postage / courier | B21: 0 | C21: 0 | D21: 0 | E21: 0 | F21: 0 | G21: 0 | H21: 0 | I21: 0 | J21: 0 | K21: 0 | L21: 0 | M21: 0 | N21: =SUM(B21:M21) -> 0
A22: Rent (studio / clinic / market stall) | B22: 0 | C22: 0 | D22: 0 | E22: 0 | F22: 0 | G22: 0 | H22: 0 | I22: 0 | J22: 0 | K22: 0 | L22: 0 | M22: 0 | N22: =SUM(B22:M22) -> 0
A23: Licenses & permits | B23: 0 | C23: 0 | D23: 0 | E23: 0 | F23: 0 | G23: 0 | H23: 0 | I23: 0 | J23: 0 | K23: 0 | L23: 0 | M23: 0 | N23: =SUM(B23:M23) -> 0
A24: Insurance - professional indemnity | B24: 0 | C24: 0 | D24: 0 | E24: 0 | F24: 0 | G24: 0 | H24: 0 | I24: 0 | J24: 0 | K24: 0 | L24: 0 | M24: 0 | N24: =SUM(B24:M24) -> 0
A25: Insurance - public liability | B25: 0 | C25: 0 | D25: 0 | E25: 0 | F25: 0 | G25: 0 | H25: 0 | I25: 0 | J25: 0 | K25: 0 | L25: 0 | M25: 0 | N25: =SUM(B25:M25) -> 0
A26: Phone / internet / mobile (business %) | B26: 0 | C26: 0 | D26: 0 | E26: 0 | F26: 0 | G26: 0 | H26: 0 | I26: 0 | J26: 0 | K26: 0 | L26: 0 | M26: 0 | N26: =SUM(B26:M26) -> 0
A27: Fuel (business %) | B27: 0 | C27: 0 | D27: 0 | E27: 0 | F27: 0 | G27: 0 | H27: 0 | I27: 0 | J27: 0 | K27: 0 | L27: 0 | M27: 0 | N27: =SUM(B27:M27) -> 0
A28: Vehicle costs (business %) | B28: 0 | C28: 0 | D28: 0 | E28: 0 | F28: 0 | G28: 0 | H28: 0 | I28: 0 | J28: 0 | K28: 0 | L28: 0 | M28: 0 | N28: =SUM(B28:M28) -> 0
A29: Bank charges | B29: 0 | C29: 0 | D29: 0 | E29: 0 | F29: 0 | G29: 0 | H29: 0 | I29: 0 | J29: 0 | K29: 0 | L29: 0 | M29: 0 | N29: =SUM(B29:M29) -> 0
A30: Subscriptions / software | B30: 0 | C30: 0 | D30: 0 | E30: 0 | F30: 0 | G30: 0 | H30: 0 | I30: 0 | J30: 0 | K30: 0 | L30: 0 | M30: 0 | N30: =SUM(B30:M30) -> 0
A31: Professional development / training | B31: 0 | C31: 0 | D31: 0 | E31: 0 | F31: 0 | G31: 0 | H31: 0 | I31: 0 | J31: 0 | K31: 0 | L31: 0 | M31: 0 | N31: =SUM(B31:M31) -> 0
... A37: Drawings (money you take out for yourself) | B37: 0 | C37: 0 | D37: 0 | E37: 0 | F37: 0 | G37: 0 | H37: 0 | I37: 0 | J37: 0 | K37: 0 | L37: 0 | M37: 0 | N37: =SUM(B37:M37) -> 0
A38: TOTAL OVERHEAD EXPENSES | B38: =SUM(B18:B37) -> 0 | C38: =SUM(C18:C37) -> 0 | D38: =SUM(D18:D37) -> 0 | E38: =SUM(E18:E37) -> 0 | F38: =SUM(F18:F37) -> 0 | G38: =SUM(G18:G37) -> 0 | H38: =SUM(H18:H37) -> 0 | I38: =SUM(I18:I37) -> 0 | ... N38: =SUM(N18:N37) -> 0
A40: SUMMARY
A41: TOTAL CASH OUT | B41: =B12+B38 -> 0 | C41: =C12+C38 -> 0 | D41: =D12+D38 -> 0 | E41: =E12+E38 -> 0 | F41: =F12+F38 -> 0 | G41: =G12+G38 -> 0 | H41: =H12+H38 -> 0 | I41: =I12+I38 -> 0 | ... N41: =N12+N38 -> 0
A42: NET CASH | B42: =B9-B41 -> 0 | C42: =C9-C41 -> 0 | D42: =D9-D41 -> 0 | E42: =E9-E41 -> 0 | F42: =F9-F41 -> 0 | G42: =G9-G41 -> 0 | H42: =H9-H41 -> 0 | I42: =I9-I41 -> 0 | ... N42: =N9-N41 -> 0
A43: GST owing (GST collected minus GST paid) | B43: =B8-B13 -> 0 | C43: =C8-C13 -> 0 | D43: =D8-D13 -> 0 | E43: =E8-E13 -> 0 | F43: =F8-F13 -> 0 | G43: =G8-G13 -> 0 | H43: =H8-H13 -> 0 | I43: =I8-I13 -> 0 | ... N43: =N8-N13 -> 0
A44: Opening bank balance | B44: 0
A45: Closing bank balance | B45: =B44+B42 -> 0 | C45: =B45+C42 -> 0 | D45: =C45+D42 -> 0 | E45: =D45+E42 -> 0 | F45: =E45+F42 -> 0 | G45: =F45+G42 -> 0 | H45: =G45+H42 -> 0 | I45: =H45+I42 -> 0 | J45: =I45+J42 -> 0 | ... M45: =L45+M42 -> 0 | N45: =M45 -> 0

Sheet Profit & Loss
A1: PROFIT & LOSS STATEMENT - Year 1
A3: INCOME
A4: Total Sales | B4: ='Sales Forecast'!P16 -> 1
A5: Less: GST collected (if registered) | B5: ='Cash Flow Budget'!N8 -> 0
A6: Net Sales (excl. GST) | B6: =B4-B5 -> 1
A7: Less: Variable costs | B7: ='Sales Forecast'!P39 -> 0
A8: CONTRIBUTION MARGIN | B8: =B6-B7 -> 1
A10: OVERHEAD EXPENSES
A11: Accountant / bookkeeper | B11: ='Cash Flow Budget'!N18 -> 0
A12: Marketing | B12: ='Cash Flow Budget'!N19 -> 0
A13: Electricity / gas | B13: ='Cash Flow Budget'!N20 -> 0
A14: Postage / courier | B14: ='Cash Flow Budget'!N21 -> 0
A15: Rent (studio / clinic / market stall) | B15: ='Cash Flow Budget'!N22 -> 0
A16: Licenses & permits | B16: ='Cash Flow Budget'!N23 -> 0
A17: Insurance - professional indemnity | B17: ='Cash Flow Budget'!N24 -> 0
A18: Insurance - public liability | B18: ='Cash Flow Budget'!N25 -> 0
A19: Phone / internet / mobile (business %) | B19: ='Cash Flow Budget'!N26 -> 0
A20: Fuel (business %) | B20: ='Cash Flow Budget'!N27 -> 0
A21: Vehicle costs (business %) | B21: ='Cash Flow Budget'!N28 -> 0
A22: Bank charges | B22: ='Cash Flow Budget'!N29 -> 0
... A29: Personal super contributions | B29: ='Cash Flow Budget'!N36 -> 0
A30: Total Overhead Expenses | B30: =SUM(B11:B29) -> 0
A31: NET PROFIT BEFORE DRAWINGS | B31: =B8-B30 -> 1
A32: Less: Drawings | B32: ='Cash Flow Budget'!N37 -> 0
A33: NET PROFIT BEFORE TAX | B33: =B31-B32 -> 1
A35: TAX CALCULATION (2024-25 ATO Rates - Sole Trader)
A36: Taxable income | B36: =MAX(0,B33) -> 1
A37: Estimated income tax | B37: =IF(B36<=0,0,IF(B36<=18200,0,IF(B36<=45500,(B36-18200)*0.19,IF(B36<=120000,5092+(B36-45500)*0.325,IF(B36<=180000,29467+(B36-120000)*0.37,51667+(B36-180000)*0.45))))) -> 0
A38: Medicare Levy (2%) | B38: =IF(B36>26000,B36*0.02,0) -> 0
A39: Total tax payable | B39: =B37+B38 -> 0
A40: NET PROFIT AFTER TAX | B40: =B33-B39 -> 1

Sheet Dashboard
A1: SOLID GROUND - Financial Dashboard
A2: Your Year 1 snapshot. All figures are projections - update your other sheets to see these change.
A4: BUSINESS INFORMATION
A5: Business name | B5: =Setup!B5 -> 0
A6: Owner name | B6: =Setup!B6 -> 0
A7: Business structure | B7: =Setup!B8 -> Sole Trader
A8: Start date | B8: =Setup!B7 -> 0
A9: GST registered? | B9: =Setup!B9 -> 0
A11: KEY NUMBERS - Year 1 Projections
A12: Total projected sales | B12: ='Sales Forecast'!P16 -> 1
A13: Contribution margin % | B13: =IFERROR('Profit & Loss'!B8/'Profit & Loss'!B6,0) -> 1
A14: Total overhead expenses | B14: ='Cash Flow Budget'!N38 -> 0
A15: Net profit before tax | B15: ='Profit & Loss'!B33 -> 1
A16: Net profit after tax | B16: ='Profit & Loss'!B40 -> 1
A17: Cash at end of Year 1 | B17: ='Cash Flow Budget'!M45 -> 0
A21: HOUSEHOLD FINANCES
A22: Total personal income (annual) | B22: ='Household Budget'!N11 -> 0
A23: Total personal expenses (annual) | B23: ='Household Budget'!N40 -> 0
A24: Household surplus / deficit | B24: ='Household Budget'!N11-'Household Budget'!N40 -> 0
